/home/as12453/miniconda3/envs/dsga3001/lib/python3.8/site-packages/lenskit/metrics/topn.py:111: RuntimeWarning: invalid value encountered in double_scalars
  return achieved / ideal
Bias models validation prediction scores by damping factor:
   damping_factor      rmse       mae
0               0  1.289824  1.000505
1               2  1.173213  0.938803
2               5  1.163368  0.930832
3              10  1.163940  0.935237
4              15  1.165523  0.938592
Bias models validation evaluations by damping factor:
               recip_rank           precision@10           precision@100  \
                     mean       std         mean       std          mean   
damping_factor                                                             
0                0.000109  0.006027     0.000033  0.001808      0.000026   
2                0.001055  0.025191     0.000229  0.004779      0.000121   
5                0.001049  0.025161     0.000229  0.004779      0.000222   
10               0.001467  0.026194     0.000556  0.007435      0.000271   
15               0.001575  0.026734     0.000588  0.007650      0.000271   

                         recall@10           recall@100                ndcg  \
                     std      mean       std       mean       std      mean   
damping_factor                                                                
0               0.000511  0.000082  0.004520   0.002370  0.047999  0.000291   
2               0.001093  0.002288  0.047790   0.009849  0.095631  0.002370   
5               0.001497  0.002288  0.047790   0.017740  0.126180  0.002293   
10              0.001645  0.004904  0.067484   0.022235  0.141757  0.003295   
15              0.001645  0.005067  0.068075   0.022235  0.141757  0.003381   

                          
                     std  
damping_factor            
0               0.013560  
2               0.046285  
5               0.045590  
10              0.048930  
15              0.049542  
Best Hyperparameters:
Damping value = 15
Best Bias Model Test Evaluations:
/home/as12453/miniconda3/envs/dsga3001/lib/python3.8/site-packages/lenskit/metrics/topn.py:111: RuntimeWarning: invalid value encountered in double_scalars
  return achieved / ideal
concurrent.futures.process._RemoteTraceback: 
"""
Traceback (most recent call last):
  File "/home/as12453/miniconda3/envs/dsga3001/lib/python3.8/concurrent/futures/process.py", line 239, in _process_worker
    r = call_item.fn(*call_item.args, **call_item.kwargs)
  File "/home/as12453/miniconda3/envs/dsga3001/lib/python3.8/concurrent/futures/process.py", line 198, in _process_chunk
    return [fn(*args) for args in chunk]
  File "/home/as12453/miniconda3/envs/dsga3001/lib/python3.8/concurrent/futures/process.py", line 198, in <listcomp>
    return [fn(*args) for args in chunk]
  File "/home/as12453/miniconda3/envs/dsga3001/lib/python3.8/site-packages/lenskit/util/parallel.py", line 131, in _mp_invoke_worker
    return __work_func(model, *args)
  File "/home/as12453/miniconda3/envs/dsga3001/lib/python3.8/site-packages/lenskit/topn.py", line 37, in _rla_worker
    return model._compute_group(col, val)
  File "/home/as12453/miniconda3/envs/dsga3001/lib/python3.8/site-packages/lenskit/topn.py", line 75, in _compute_group
    return pd.DataFrame.from_records(gen, columns=self.rec_key + mnames)
  File "/home/as12453/miniconda3/envs/dsga3001/lib/python3.8/site-packages/pandas/core/frame.py", line 1751, in from_records
    first_row = next(data)
  File "/home/as12453/miniconda3/envs/dsga3001/lib/python3.8/site-packages/lenskit/topn.py", line 86, in _iter_measurements
    g_truth = self.truth[tk]
KeyError: (1, '--BumyUHiO_7YsHurb9Hkw')
"""

The above exception was the direct cause of the following exception:

Traceback (most recent call last):
  File "./Bias_and_BiasMF_Models.py", line 304, in <module>
    main()
  File "./Bias_and_BiasMF_Models.py", line 157, in main
    results_10recs = rla.compute(recs_10_, test_binary_)
  File "/home/as12453/miniconda3/envs/dsga3001/lib/python3.8/site-packages/lenskit/topn.py", line 176, in compute
    res = job.compute(self.n_jobs)
  File "/home/as12453/miniconda3/envs/dsga3001/lib/python3.8/site-packages/lenskit/topn.py", line 67, in compute
    res = pd.concat(res, ignore_index=True)
  File "/home/as12453/miniconda3/envs/dsga3001/lib/python3.8/site-packages/pandas/core/reshape/concat.py", line 274, in concat
    op = _Concatenator(
  File "/home/as12453/miniconda3/envs/dsga3001/lib/python3.8/site-packages/pandas/core/reshape/concat.py", line 328, in __init__
    objs = list(objs)
  File "/home/as12453/miniconda3/envs/dsga3001/lib/python3.8/concurrent/futures/process.py", line 484, in _chain_from_iterable_of_lists
    for element in iterable:
  File "/home/as12453/miniconda3/envs/dsga3001/lib/python3.8/concurrent/futures/_base.py", line 611, in result_iterator
    yield fs.pop().result()
  File "/home/as12453/miniconda3/envs/dsga3001/lib/python3.8/concurrent/futures/_base.py", line 439, in result
    return self.__get_result()
  File "/home/as12453/miniconda3/envs/dsga3001/lib/python3.8/concurrent/futures/_base.py", line 388, in __get_result
    raise self._exception
KeyError: (1, '--BumyUHiO_7YsHurb9Hkw')
