Bias Model Validation RMSE Scores:
Damping Value: 0
Damping Value: 1
/home/as12453/miniconda3/envs/dsga3001/lib/python3.8/site-packages/lenskit/metrics/topn.py:111: RuntimeWarning: invalid value encountered in double_scalars
  return achieved / ideal
Damping Value: 5
Damping Value: 10
Damping Value: 15
Bias models validation prediction scores by damping factor:
   damping_factor      rmse       mae
0               0  1.299990  1.000879
1               1  1.197137  0.952927
2               5  1.165607  0.930412
3              10  1.166187  0.935343
4              15  1.167909  0.938889
Bias models validation evaluations by damping factor:
               recip_rank           precision@10           precision@100  \
                     mean       std         mean       std          mean   
damping_factor                                                             
0                0.000054  0.003013     0.000033  0.001808      0.000046   
1                0.001230  0.032096     0.000229  0.004779      0.000137   
5                0.001774  0.035307     0.000425  0.006506      0.000212   
10               0.001633  0.031751     0.000425  0.006506      0.000235   
15               0.001695  0.031948     0.000458  0.006751      0.000235   

                         recall@10           recall@100                ndcg  \
                     std      mean       std       mean       std      mean   
damping_factor                                                                
0               0.000675  0.000327  0.018080   0.004114  0.062960  0.000000   
1               0.001164  0.001880  0.041638   0.011551  0.102951  0.001806   
5               0.001442  0.003841  0.060701   0.017936  0.128348  0.003414   
10              0.001516  0.003580  0.058074   0.020007  0.135621  0.003344   
15              0.001516  0.003907  0.060804   0.020388  0.137527  0.003391   

                          
                     std  
damping_factor            
0               0.000000  
1               0.036068  
5               0.049854  
10              0.049621  
15              0.049994  
Best Hyperparameters:
Damping value = 5
Best Bias Model Test Evaluations:
/home/as12453/miniconda3/envs/dsga3001/lib/python3.8/site-packages/lenskit/metrics/topn.py:111: RuntimeWarning: invalid value encountered in double_scalars
  return achieved / ideal
/home/as12453/miniconda3/envs/dsga3001/lib/python3.8/site-packages/lenskit/metrics/topn.py:111: RuntimeWarning: invalid value encountered in double_scalars
  return achieved / ideal
/home/as12453/miniconda3/envs/dsga3001/lib/python3.8/site-packages/lenskit/metrics/topn.py:111: RuntimeWarning: invalid value encountered in double_scalars
  return achieved / ideal
/home/as12453/miniconda3/envs/dsga3001/lib/python3.8/site-packages/lenskit/metrics/topn.py:111: RuntimeWarning: invalid value encountered in double_scalars
  return achieved / ideal
concurrent.futures.process._RemoteTraceback: 
"""
Traceback (most recent call last):
  File "/home/as12453/miniconda3/envs/dsga3001/lib/python3.8/concurrent/futures/process.py", line 239, in _process_worker
    r = call_item.fn(*call_item.args, **call_item.kwargs)
  File "/home/as12453/miniconda3/envs/dsga3001/lib/python3.8/concurrent/futures/process.py", line 198, in _process_chunk
    return [fn(*args) for args in chunk]
  File "/home/as12453/miniconda3/envs/dsga3001/lib/python3.8/concurrent/futures/process.py", line 198, in <listcomp>
    return [fn(*args) for args in chunk]
  File "/home/as12453/miniconda3/envs/dsga3001/lib/python3.8/site-packages/lenskit/util/parallel.py", line 131, in _mp_invoke_worker
    return __work_func(model, *args)
  File "/home/as12453/miniconda3/envs/dsga3001/lib/python3.8/site-packages/lenskit/topn.py", line 37, in _rla_worker
    return model._compute_group(col, val)
  File "/home/as12453/miniconda3/envs/dsga3001/lib/python3.8/site-packages/lenskit/topn.py", line 75, in _compute_group
    return pd.DataFrame.from_records(gen, columns=self.rec_key + mnames)
  File "/home/as12453/miniconda3/envs/dsga3001/lib/python3.8/site-packages/pandas/core/frame.py", line 1751, in from_records
    first_row = next(data)
  File "/home/as12453/miniconda3/envs/dsga3001/lib/python3.8/site-packages/lenskit/topn.py", line 93, in _iter_measurements
    results = tuple(mf(df, g_truth, **margs) for (mf, mn, margs) in self.metrics)
  File "/home/as12453/miniconda3/envs/dsga3001/lib/python3.8/site-packages/lenskit/topn.py", line 93, in <genexpr>
    results = tuple(mf(df, g_truth, **margs) for (mf, mn, margs) in self.metrics)
  File "/home/as12453/miniconda3/envs/dsga3001/lib/python3.8/site-packages/lenskit/metrics/topn.py", line 98, in ndcg
    tpos = truth.index.get_indexer(recs['item'])
  File "/home/as12453/miniconda3/envs/dsga3001/lib/python3.8/site-packages/pandas/core/indexes/base.py", line 2980, in get_indexer
    raise InvalidIndexError(
pandas.errors.InvalidIndexError: Reindexing only valid with uniquely valued Index objects
"""

The above exception was the direct cause of the following exception:

Traceback (most recent call last):
  File "./Bias_and_BiasMF_Models.py", line 193, in <module>
    main()
  File "./Bias_and_BiasMF_Models.py", line 173, in main
    results_10recs = rla.compute(recs_10, test_binary)
  File "/home/as12453/miniconda3/envs/dsga3001/lib/python3.8/site-packages/lenskit/topn.py", line 176, in compute
    res = job.compute(self.n_jobs)
  File "/home/as12453/miniconda3/envs/dsga3001/lib/python3.8/site-packages/lenskit/topn.py", line 67, in compute
    res = pd.concat(res, ignore_index=True)
  File "/home/as12453/miniconda3/envs/dsga3001/lib/python3.8/site-packages/pandas/core/reshape/concat.py", line 274, in concat
    op = _Concatenator(
  File "/home/as12453/miniconda3/envs/dsga3001/lib/python3.8/site-packages/pandas/core/reshape/concat.py", line 328, in __init__
    objs = list(objs)
  File "/home/as12453/miniconda3/envs/dsga3001/lib/python3.8/concurrent/futures/process.py", line 484, in _chain_from_iterable_of_lists
    for element in iterable:
  File "/home/as12453/miniconda3/envs/dsga3001/lib/python3.8/concurrent/futures/_base.py", line 611, in result_iterator
    yield fs.pop().result()
  File "/home/as12453/miniconda3/envs/dsga3001/lib/python3.8/concurrent/futures/_base.py", line 439, in result
    return self.__get_result()
  File "/home/as12453/miniconda3/envs/dsga3001/lib/python3.8/concurrent/futures/_base.py", line 388, in __get_result
    raise self._exception
pandas.errors.InvalidIndexError: Reindexing only valid with uniquely valued Index objects
